<?xml version="1.0" ?>
<sdf version="1.8">
    <model name='vehicle'>
      <link name='chassis'>
        <pose>-0.151427 -0 0.175 0 -0 0</pose>
        <inertial>
          <mass>1.14395</mass>
          <inertia>
            <ixx>0.126164</ixx>
            <ixy>0</ixy>
            <ixz>0</ixz>
            <iyy>0.416519</iyy>
            <iyz>0</iyz>
            <izz>0.481014</izz>
          </inertia>
        </inertial>
        <visual name="chassis_visual">
          <geometry>
            <box>
              <size>2.01142 1 0.568726</size>
            </box>
          </geometry>
          <material>
            <ambient>0.05 0.05 0.6 1</ambient>
            <diffuse>0.1 0.1 0.9 1</diffuse>
            <specular>0.5 0.5 0.5 1</specular>
          </material>
        </visual>
        <collision name='collision_chassis'>
          <geometry>
            <box>
              <size>2.01142 1 0.568726</size>
            </box>
          </geometry>
        </collision>
      </link>

      <link name='lidar_link'>
        <pose>0.6 0 0.6 0 0 0</pose>
        <inertial>
          <mass>0.1</mass>
          <inertia>
            <ixx>0.0001</ixx>
            <ixy>0</ixy>
            <ixz>0</ixz>
            <iyy>0.0001</iyy>
            <iyz>0</iyz>
            <izz>0.0001</izz>
          </inertia>
        </inertial>

        <visual name='lidar_visual'>
          <geometry>
            <cylinder>
              <radius>0.2</radius>
              <length>0.3</length>
            </cylinder>
          </geometry>
          <material>
            <ambient>0.1 0.1 0.1 1</ambient>
            <diffuse>0.1 0.1 0.1 1</diffuse>
            <specular>0.1 0.1 0.1 1</specular>
          </material>
        </visual>

        <sensor name="gpu_lidar" type="gpu_lidar">
          <topic>/lidar</topic>
          <update_rate>20</update_rate>
          <visualize>true</visualize>
          <lidar>
            <scan>
              <horizontal>
                <samples>360</samples> <resolution>1</resolution> <min_angle>-3.14159</min_angle>
                <max_angle>3.14159</max_angle>
              </horizontal>
            </scan>
            <range>
              <min>0.2</min>    <max>12.0</max>   <resolution>0.01</resolution>
            </range>
            <noise>
              <type>gaussian</type>
              <mean>0.0</mean>
              <stddev>0.02</stddev>
            </noise>
          </lidar>
        </sensor>
      </link>

      <link name='imu_link'>
        <pose>0 0 0.3 0 0 0</pose>
        <inertial>
          <mass>0.01</mass>
          <inertia>
            <ixx>1.6e-6</ixx>
            <ixy>0</ixy>
            <ixz>0</ixz>
            <iyy>1.6e-6</iyy>
            <iyz>0</iyz>
            <izz>1.6e-6</izz>
          </inertia>
        </inertial>

        <sensor name="imu_sensor" type="imu">
          <topic>/imu</topic>
          <update_rate>20</update_rate>
          <always_on>true</always_on>
          <visualize>true</visualize>
          <imu>
              <angular_velocity>
                <x>
                  <noise type='gaussian'>
                    <mean>0.0</mean>
                    <stddev>0.005</stddev>
                  </noise>
                </x>
                <y>
                  <noise type='gaussian'>
                    <mean>0.0</mean>
                    <stddev>0.005</stddev>
                  </noise>
                </y>
                <z>
                  <noise type='gaussian'>
                    <mean>0.0</mean>
                    <stddev>0.005</stddev>
                  </noise>
                </z>
              </angular_velocity>
              <linear_acceleration>
                <x>
                  <noise type='gaussian'>
                    <mean>0.0</mean>
                    <stddev>0.01</stddev>
                  </noise>
                </x>
                <y>
                  <noise type='gaussian'>
                    <mean>0.0</mean>
                    <stddev>0.01</stddev>
                  </noise>
                </y>
                <z>
                  <noise type='gaussian'>
                    <mean>0.0</mean>
                    <stddev>0.01</stddev>
                  </noise>
                </z>
              </linear_acceleration>
          </imu>
        </sensor>
      </link>

      <link name='left_wheel'>
        <pose>0.554283 0.625029 -0.025 -1.5707 0 0</pose>
        <inertial>
          <mass>2</mass>
          <inertia>
            <ixx>0.145833</ixx>
            <ixy>0</ixy>
            <ixz>0</ixz>
            <iyy>0.145833</iyy>
            <iyz>0</iyz>
            <izz>0.125</izz>
          </inertia>
        </inertial>
        <visual name='visual_left_wheel'>
          <geometry>
            <sphere>
              <radius>0.3</radius>
            </sphere>
          </geometry>
          <material>
            <ambient>0.2 0.2 0.2 1</ambient>
            <diffuse>0.2 0.2 0.2 1</diffuse>
            <specular>0.2 0.2 0.2 1</specular>
          </material>
        </visual>
        <collision name='collision_left_wheel'>
          <geometry>
            <sphere>
              <radius>0.3</radius>
            </sphere>
          </geometry>
          <surface>
            <friction>
              <ode>
                <mu>1.0</mu>   <mu2>0.8</mu2>  <slip1>0.05</slip1> <slip2>0.05</slip2> </ode>
            </friction>
            <contact>
              <ode>
                <min_depth>0.001</min_depth>
                <kp>1e8</kp>
              </ode>
            </contact>
        </surface>
        </collision>
      </link>

      <link name='right_wheel'>
        <pose>0.554282 -0.625029 -0.025 -1.5707 0 0</pose>
        <inertial>
          <mass>2</mass>
          <inertia>
            <ixx>0.145833</ixx>
            <ixy>0</ixy>
            <ixz>0</ixz>
            <iyy>0.145833</iyy>
            <iyz>0</iyz>
            <izz>0.125</izz>
          </inertia>
        </inertial>
        <visual name='visual_right_wheel'>
          <geometry>
            <sphere>
              <radius>0.3</radius>
            </sphere>
          </geometry>
          <material>
            <ambient>0.2 0.2 0.2 1</ambient>
            <diffuse>0.2 0.2 0.2 1</diffuse>
            <specular>0.2 0.2 0.2 1</specular>
          </material>
        </visual>
        <collision name='collision_right_wheel'>
          <geometry>
            <sphere>
              <radius>0.3</radius>
            </sphere>
          </geometry>
            <surface>
              <friction>
                <ode>
                  <mu>1.0</mu>   <mu2>0.8</mu2>  <slip1>0.05</slip1> <slip2>0.05</slip2> </ode>
              </friction>
              <contact>
                <ode>
                  <min_depth>0.001</min_depth>
                  <kp>1e8</kp>
                </ode>
              </contact>
            </surface>
        </collision>
      </link>

      <link name='caster'>
        <pose>-0.957138 -0 -0.125 0 -0 0</pose>
        <inertial>
          <mass>1</mass>
          <inertia>
            <ixx>0.1</ixx>
            <ixy>0</ixy>
            <ixz>0</ixz>
            <iyy>0.1</iyy>
            <iyz>0</iyz>
            <izz>0.1</izz>
          </inertia>
        </inertial>
        <visual name='visual_caster'>
          <geometry>
            <sphere>
              <radius>0.2</radius>
            </sphere>
          </geometry>
          <material>
            <ambient>0.2 0.2 0.2 1</ambient>
            <diffuse>0.2 0.2 0.2 1</diffuse>
            <specular>0.2 0.2 0.2 1</specular>
          </material>
        </visual>
        <collision name='collision_caster'>
          <geometry>
            <sphere>
              <radius>0.2</radius>
            </sphere>
          </geometry>
        </collision>
      </link>

      <joint name='lidar_joint' type='fixed'>
        <parent>chassis</parent>
        <child>lidar_link</child>
      </joint>

      <joint name='imu_joint' type='fixed'>
        <parent>chassis</parent>
        <child>imu_link</child>
      </joint>

      <joint name='left_wheel_joint' type='revolute'>
        <parent>chassis</parent>
        <child>left_wheel</child>
        <axis>
          <xyz>0 0 1</xyz>  <!-- rotate around Y to roll forward -->
          <limit>
            <lower>-1.79769e+308</lower>
            <upper>1.79769e+308</upper>
          </limit>
        </axis>
      </joint>

      <joint name='right_wheel_joint' type='revolute'>
        <parent>chassis</parent>
        <child>right_wheel</child>
        <axis>
          <xyz>0 0 1</xyz>  <!-- rotate around Y to roll forward -->
          <limit>
            <lower>-1.79769e+308</lower>
            <upper>1.79769e+308</upper>
          </limit>
        </axis>
      </joint>

      <joint name='caster_wheel' type='ball'>
        <parent>chassis</parent>
        <child>caster</child>
      </joint>

      <plugin
        filename="ignition-gazebo-diff-drive-system"
        name="ignition::gazebo::systems::DiffDrive">
        <odom_noise_xyz>0.001 0.001 0.001</odom_noise_xyz>
        <odom_noise_rpy>0.001 0.001 0.001</odom_noise_rpy>
        <left_joint>left_wheel_joint</left_joint>
        <right_joint>right_wheel_joint</right_joint>
        <wheel_separation>1.25</wheel_separation>
        <wheel_radius>0.3</wheel_radius>
        <odom_publish_frequency>20</odom_publish_frequency>
        <max_linear_acceleration>1</max_linear_acceleration>
        <min_linear_acceleration>-1</min_linear_acceleration>
        <max_angular_acceleration>2</max_angular_acceleration>
        <min_angular_acceleration>-2</min_angular_acceleration>
        <max_linear_velocity>0.5</max_linear_velocity>
        <min_linear_velocity>-0.5</min_linear_velocity>
        <max_angular_velocity>1</max_angular_velocity>
        <min_angular_velocity>-1</min_angular_velocity>
      </plugin>

    </model>
</sdf>
