<?xml version="1.0" ?>
<sdf version="1.8">
    <model name='vehicle'>
      <link name='chassis'>
        <pose>-0.151427 -0 0.175 0 -0 0</pose>
        <inertial>
          <mass>1.14395</mass>
          <inertia>
            <ixx>0.126164</ixx>
            <ixy>0</ixy>
            <ixz>0</ixz>
            <iyy>0.416519</iyy>
            <iyz>0</iyz>
            <izz>0.481014</izz>
          </inertia>
        </inertial>
        <visual name="chassis_visual">
          <geometry>
            <box>
              <size>2.01142 1 0.568726</size>
            </box>
          </geometry>
          <material>
            <ambient>0.05 0.5 0.05 1</ambient>
            <diffuse>0.1 0.9 0.1 1</diffuse>
            <specular>0.5 0.5 0.5 1</specular>
          </material>
        </visual>
        <collision name='collision_chassis'>
          <geometry>
            <box>
              <size>2.01142 1 0.568726</size>
            </box>
          </geometry>
        </collision>

        <!-- RGB-D camera mounted on the chassis -->
        <sensor name="rgbd" type="rgbd_camera">
          <!-- x forward, raise a bit -->
          <pose>0.30 0 0.40 0 0 0</pose>
          <always_on>true</always_on>
          <update_rate>20</update_rate>
          <visualize>true</visualize>

          <!-- Base topic; Ign will publish /camera/image and /camera/depth_image -->
          <topic>/camera</topic>

          <camera>
            <horizontal_fov>1.047</horizontal_fov> <!-- ~60 deg -->
            <image>
              <width>640</width>
              <height>480</height>
              <format>R8G8B8</format>
            </image>
            <clip>
              <near>0.1</near>
              <far>15.0</far>
            </clip>
          </camera>
        </sensor>

        <!-- camera visual box -->
        <visual name="camera_box_visual">
          <pose>0.30 0 0.40 0 0 0</pose>
          <geometry><box><size>0.30 0.20 0.20</size></box></geometry> <!-- 5x -->
          <material>
            <ambient>0.02 0.02 0.02 1</ambient>
            <diffuse>0.02 0.02 0.02 1</diffuse>
            <specular>0.1 0.1 0.1 1</specular>
          </material>
        </visual>
      </link>

      <link name='left_wheel'>
        <pose>0.554283 0.625029 -0.025 -1.5707 0 0</pose>
        <inertial>
          <mass>2</mass>
          <inertia>
            <ixx>0.145833</ixx>
            <ixy>0</ixy>
            <ixz>0</ixz>
            <iyy>0.145833</iyy>
            <iyz>0</iyz>
            <izz>0.125</izz>
          </inertia>
        </inertial>
        <visual name='visual_left_wheel'>
          <geometry>
            <sphere>
              <radius>0.3</radius>
            </sphere>
          </geometry>
          <material>
            <ambient>0.2 0.2 0.2 1</ambient>
            <diffuse>0.2 0.2 0.2 1</diffuse>
            <specular>0.2 0.2 0.2 1</specular>
          </material>
        </visual>
        <collision name='collision_left_wheel'>
          <geometry>
            <sphere>
              <radius>0.3</radius>
            </sphere>
          </geometry>
        </collision>
      </link>

      <link name='right_wheel'>
        <pose>0.554282 -0.625029 -0.025 -1.5707 0 0</pose>
        <inertial>
          <mass>2</mass>
          <inertia>
            <ixx>0.145833</ixx>
            <ixy>0</ixy>
            <ixz>0</ixz>
            <iyy>0.145833</iyy>
            <iyz>0</iyz>
            <izz>0.125</izz>
          </inertia>
        </inertial>
        <visual name='visual_right_wheel'>
          <geometry>
            <sphere>
              <radius>0.3</radius>
            </sphere>
          </geometry>
          <material>
            <ambient>0.2 0.2 0.2 1</ambient>
            <diffuse>0.2 0.2 0.2 1</diffuse>
            <specular>0.2 0.2 0.2 1</specular>
          </material>
        </visual>
        <collision name='collision_right_wheel'>
          <geometry>
            <sphere>
              <radius>0.3</radius>
            </sphere>
          </geometry>
        </collision>
      </link>

      <link name='caster'>
        <pose>-0.957138 -0 -0.125 0 -0 0</pose>
        <inertial>
          <mass>1</mass>
          <inertia>
            <ixx>0.1</ixx>
            <ixy>0</ixy>
            <ixz>0</ixz>
            <iyy>0.1</iyy>
            <iyz>0</iyz>
            <izz>0.1</izz>
          </inertia>
        </inertial>
        <visual name='visual_caster'>
          <geometry>
            <sphere>
              <radius>0.2</radius>
            </sphere>
          </geometry>
          <material>
            <ambient>0.2 0.2 0.2 1</ambient>
            <diffuse>0.2 0.2 0.2 1</diffuse>
            <specular>0.2 0.2 0.2 1</specular>
          </material>
        </visual>
        <collision name='collision_caster'>
          <geometry>
            <sphere>
              <radius>0.2</radius>
            </sphere>
          </geometry>
        </collision>
      </link>

      <link name="camera_link_green">
        <pose>0.3 0 0.4 0 0 0</pose>
        <inertial><mass>0.1</mass></inertial>
        <!-- No duplicate sensor here; the chassis rgbd sensor is the single source -->
      </link>

      <joint name='left_wheel_joint' type='revolute'>
        <parent>chassis</parent>
        <child>left_wheel</child>
        <axis>
          <xyz>0 0 1</xyz>
          <limit>
            <lower>-1.79769e+308</lower>
            <upper>1.79769e+308</upper>
          </limit>
        </axis>
      </joint>

      <joint name='right_wheel_joint' type='revolute'>
        <parent>chassis</parent>
        <child>right_wheel</child>
        <axis>
          <xyz>0 0 1</xyz>
          <limit>
            <lower>-1.79769e+308</lower>
            <upper>1.79769e+308</upper>
          </limit>
        </axis>
      </joint>

      <joint name='caster_wheel' type='ball'>
        <parent>chassis</parent>
        <child>caster</child>
      </joint>

      <plugin
        filename="ignition-gazebo-diff-drive-system"
        name="ignition::gazebo::systems::DiffDrive">
        <left_joint>left_wheel_joint</left_joint>
        <right_joint>right_wheel_joint</right_joint>
        <wheel_separation>1.25</wheel_separation>
        <wheel_radius>0.3</wheel_radius>
        <odom_publish_frequency>1</odom_publish_frequency>
        <max_linear_acceleration>1</max_linear_acceleration>
        <min_linear_acceleration>-1</min_linear_acceleration>
        <max_angular_acceleration>2</max_angular_acceleration>
        <min_angular_acceleration>-2</min_angular_acceleration>
        <max_linear_velocity>0.5</max_linear_velocity>
        <min_linear_velocity>-0.5</min_linear_velocity>
        <max_angular_velocity>1</max_angular_velocity>
        <min_angular_velocity>-1</min_angular_velocity>
      </plugin>

    </model>
</sdf>
